2024-12-11 18:23:08,015 INFO file_cache is only supported with oauth2client<4.0.0
2024-12-11 18:23:08,343 INFO Update id=301615574 is not handled. Duration 333 ms by bot id=7546513983
2024-12-11 18:23:08,343 ERROR Cause exception while process update id=301615574 by bot id=7546513983
HttpError: <HttpError 404 when requesting https://www.googleapis.com/calendar/v3/calendars/%7B%7D/events?timeMin=2024-12-11T18%3A22%3A40Z&timeMax=2024-12-11T18%3A23%3A08Z&singleEvents=true&orderBy=startTime&alt=json returned "Not Found". Details: "[{'domain': 'global', 'reason': 'notFound', 'message': 'Not Found'}]">
Traceback (most recent call last):
  File "/Users/matvei/PycharmProjects/testoviy/.venv/lib/python3.9/site-packages/aiogram/dispatcher/dispatcher.py", line 309, in _process_update
    response = await self.feed_update(bot, update, **kwargs)
  File "/Users/matvei/PycharmProjects/testoviy/.venv/lib/python3.9/site-packages/aiogram/dispatcher/dispatcher.py", line 158, in feed_update
    response = await self.update.wrap_outer_middleware(
  File "/Users/matvei/PycharmProjects/testoviy/.venv/lib/python3.9/site-packages/aiogram/dispatcher/middlewares/error.py", line 25, in __call__
    return await handler(event, data)
  File "/Users/matvei/PycharmProjects/testoviy/.venv/lib/python3.9/site-packages/aiogram/dispatcher/middlewares/user_context.py", line 56, in __call__
    return await handler(event, data)
  File "/Users/matvei/PycharmProjects/testoviy/.venv/lib/python3.9/site-packages/aiogram/fsm/middleware.py", line 42, in __call__
    return await handler(event, data)
  File "/Users/matvei/PycharmProjects/testoviy/.venv/lib/python3.9/site-packages/aiogram/dispatcher/event/telegram.py", line 121, in trigger
    return await wrapped_inner(event, kwargs)
  File "/Users/matvei/PycharmProjects/testoviy/.venv/lib/python3.9/site-packages/aiogram/dispatcher/event/handler.py", line 43, in call
    return await wrapped()
  File "/Users/matvei/PycharmProjects/testoviy/.venv/lib/python3.9/site-packages/aiogram/dispatcher/dispatcher.py", line 276, in _listen_update
    return await self.propagate_event(update_type=update_type, event=event, **kwargs)
  File "/Users/matvei/PycharmProjects/testoviy/.venv/lib/python3.9/site-packages/aiogram/dispatcher/router.py", line 146, in propagate_event
    return await observer.wrap_outer_middleware(_wrapped, event=event, data=kwargs)
  File "/Users/matvei/PycharmProjects/testoviy/.venv/lib/python3.9/site-packages/aiogram/dispatcher/router.py", line 141, in _wrapped
    return await self._propagate_event(
  File "/Users/matvei/PycharmProjects/testoviy/.venv/lib/python3.9/site-packages/aiogram/dispatcher/router.py", line 174, in _propagate_event
    response = await router.propagate_event(update_type=update_type, event=event, **kwargs)
  File "/Users/matvei/PycharmProjects/testoviy/.venv/lib/python3.9/site-packages/aiogram/dispatcher/router.py", line 146, in propagate_event
    return await observer.wrap_outer_middleware(_wrapped, event=event, data=kwargs)
  File "/Users/matvei/PycharmProjects/testoviy/.venv/lib/python3.9/site-packages/aiogram/dispatcher/router.py", line 141, in _wrapped
    return await self._propagate_event(
  File "/Users/matvei/PycharmProjects/testoviy/.venv/lib/python3.9/site-packages/aiogram/dispatcher/router.py", line 166, in _propagate_event
    response = await observer.trigger(event, **kwargs)
  File "/Users/matvei/PycharmProjects/testoviy/.venv/lib/python3.9/site-packages/aiogram/dispatcher/event/telegram.py", line 121, in trigger
    return await wrapped_inner(event, kwargs)
  File "/Users/matvei/PycharmProjects/testoviy/.venv/lib/python3.9/site-packages/aiogram/dispatcher/event/handler.py", line 43, in call
    return await wrapped()
  File "/Users/matvei/PycharmProjects/testoviy/handlers.py", line 55, in recount
    errors = money_recount()
  File "/Users/matvei/PycharmProjects/testoviy/calendar_myad.py", line 61, in recount
    events_result = service.events().list(
  File "/Users/matvei/PycharmProjects/testoviy/.venv/lib/python3.9/site-packages/googleapiclient/_helpers.py", line 130, in positional_wrapper
    return wrapped(*args, **kwargs)
  File "/Users/matvei/PycharmProjects/testoviy/.venv/lib/python3.9/site-packages/googleapiclient/http.py", line 938, in execute
    raise HttpError(resp, content, uri=self.uri)
googleapiclient.errors.HttpError: <HttpError 404 when requesting https://www.googleapis.com/calendar/v3/calendars/%7B%7D/events?timeMin=2024-12-11T18%3A22%3A40Z&timeMax=2024-12-11T18%3A23%3A08Z&singleEvents=true&orderBy=startTime&alt=json returned "Not Found". Details: "[{'domain': 'global', 'reason': 'notFound', 'message': 'Not Found'}]">
2024-12-11 18:25:11,881 WARNING Received SIGINT signal
2024-12-11 18:25:11,882 INFO Polling stopped for bot @matveykalobot id=7546513983 - 'великий бот матвейки'
2024-12-11 18:25:11,882 INFO Polling stopped
2024-12-11 18:25:17,887 INFO Start polling
2024-12-11 18:25:18,133 INFO Run polling for bot @matveykalobot id=7546513983 - 'великий бот матвейки'
2024-12-11 18:25:18,232 INFO file_cache is only supported with oauth2client<4.0.0
2024-12-11 18:25:18,568 INFO Update id=301615575 is not handled. Duration 344 ms by bot id=7546513983
2024-12-11 18:25:18,568 ERROR Cause exception while process update id=301615575 by bot id=7546513983
HttpError: <HttpError 404 when requesting https://www.googleapis.com/calendar/v3/calendars/%7B%7D/events?timeMin=2024-12-11T18%3A23%3A08Z&timeMax=2024-12-11T18%3A25%3A18Z&singleEvents=true&orderBy=startTime&alt=json returned "Not Found". Details: "[{'domain': 'global', 'reason': 'notFound', 'message': 'Not Found'}]">
Traceback (most recent call last):
  File "/Users/matvei/PycharmProjects/testoviy/.venv/lib/python3.9/site-packages/aiogram/dispatcher/dispatcher.py", line 309, in _process_update
    response = await self.feed_update(bot, update, **kwargs)
  File "/Users/matvei/PycharmProjects/testoviy/.venv/lib/python3.9/site-packages/aiogram/dispatcher/dispatcher.py", line 158, in feed_update
    response = await self.update.wrap_outer_middleware(
  File "/Users/matvei/PycharmProjects/testoviy/.venv/lib/python3.9/site-packages/aiogram/dispatcher/middlewares/error.py", line 25, in __call__
    return await handler(event, data)
  File "/Users/matvei/PycharmProjects/testoviy/.venv/lib/python3.9/site-packages/aiogram/dispatcher/middlewares/user_context.py", line 56, in __call__
    return await handler(event, data)
  File "/Users/matvei/PycharmProjects/testoviy/.venv/lib/python3.9/site-packages/aiogram/fsm/middleware.py", line 42, in __call__
    return await handler(event, data)
  File "/Users/matvei/PycharmProjects/testoviy/.venv/lib/python3.9/site-packages/aiogram/dispatcher/event/telegram.py", line 121, in trigger
    return await wrapped_inner(event, kwargs)
  File "/Users/matvei/PycharmProjects/testoviy/.venv/lib/python3.9/site-packages/aiogram/dispatcher/event/handler.py", line 43, in call
    return await wrapped()
  File "/Users/matvei/PycharmProjects/testoviy/.venv/lib/python3.9/site-packages/aiogram/dispatcher/dispatcher.py", line 276, in _listen_update
    return await self.propagate_event(update_type=update_type, event=event, **kwargs)
  File "/Users/matvei/PycharmProjects/testoviy/.venv/lib/python3.9/site-packages/aiogram/dispatcher/router.py", line 146, in propagate_event
    return await observer.wrap_outer_middleware(_wrapped, event=event, data=kwargs)
  File "/Users/matvei/PycharmProjects/testoviy/.venv/lib/python3.9/site-packages/aiogram/dispatcher/router.py", line 141, in _wrapped
    return await self._propagate_event(
  File "/Users/matvei/PycharmProjects/testoviy/.venv/lib/python3.9/site-packages/aiogram/dispatcher/router.py", line 174, in _propagate_event
    response = await router.propagate_event(update_type=update_type, event=event, **kwargs)
  File "/Users/matvei/PycharmProjects/testoviy/.venv/lib/python3.9/site-packages/aiogram/dispatcher/router.py", line 146, in propagate_event
    return await observer.wrap_outer_middleware(_wrapped, event=event, data=kwargs)
  File "/Users/matvei/PycharmProjects/testoviy/.venv/lib/python3.9/site-packages/aiogram/dispatcher/router.py", line 141, in _wrapped
    return await self._propagate_event(
  File "/Users/matvei/PycharmProjects/testoviy/.venv/lib/python3.9/site-packages/aiogram/dispatcher/router.py", line 166, in _propagate_event
    response = await observer.trigger(event, **kwargs)
  File "/Users/matvei/PycharmProjects/testoviy/.venv/lib/python3.9/site-packages/aiogram/dispatcher/event/telegram.py", line 121, in trigger
    return await wrapped_inner(event, kwargs)
  File "/Users/matvei/PycharmProjects/testoviy/.venv/lib/python3.9/site-packages/aiogram/dispatcher/event/handler.py", line 43, in call
    return await wrapped()
  File "/Users/matvei/PycharmProjects/testoviy/handlers.py", line 55, in recount
    errors = money_recount()
  File "/Users/matvei/PycharmProjects/testoviy/calendar_myad.py", line 61, in recount
    events_result = service.events().list(
  File "/Users/matvei/PycharmProjects/testoviy/.venv/lib/python3.9/site-packages/googleapiclient/_helpers.py", line 130, in positional_wrapper
    return wrapped(*args, **kwargs)
  File "/Users/matvei/PycharmProjects/testoviy/.venv/lib/python3.9/site-packages/googleapiclient/http.py", line 938, in execute
    raise HttpError(resp, content, uri=self.uri)
googleapiclient.errors.HttpError: <HttpError 404 when requesting https://www.googleapis.com/calendar/v3/calendars/%7B%7D/events?timeMin=2024-12-11T18%3A23%3A08Z&timeMax=2024-12-11T18%3A25%3A18Z&singleEvents=true&orderBy=startTime&alt=json returned "Not Found". Details: "[{'domain': 'global', 'reason': 'notFound', 'message': 'Not Found'}]">
2024-12-11 18:25:41,048 WARNING Received SIGINT signal
2024-12-11 18:25:41,049 INFO Polling stopped for bot @matveykalobot id=7546513983 - 'великий бот матвейки'
2024-12-11 18:25:41,049 INFO Polling stopped
2024-12-11 18:25:46,385 INFO Start polling
2024-12-11 18:25:46,599 INFO Run polling for bot @matveykalobot id=7546513983 - 'великий бот матвейки'
2024-12-11 18:25:46,772 INFO file_cache is only supported with oauth2client<4.0.0
2024-12-11 18:25:47,081 INFO Update id=301615576 is not handled. Duration 313 ms by bot id=7546513983
2024-12-11 18:25:47,081 ERROR Cause exception while process update id=301615576 by bot id=7546513983
HttpError: <HttpError 404 when requesting https://www.googleapis.com/calendar/v3/calendars/%7B%7D/events?timeMin=2024-12-11T18%3A25%3A18Z&timeMax=2024-12-11T18%3A25%3A46Z&singleEvents=true&orderBy=startTime&alt=json returned "Not Found". Details: "[{'domain': 'global', 'reason': 'notFound', 'message': 'Not Found'}]">
Traceback (most recent call last):
  File "/Users/matvei/PycharmProjects/testoviy/.venv/lib/python3.9/site-packages/aiogram/dispatcher/dispatcher.py", line 309, in _process_update
    response = await self.feed_update(bot, update, **kwargs)
  File "/Users/matvei/PycharmProjects/testoviy/.venv/lib/python3.9/site-packages/aiogram/dispatcher/dispatcher.py", line 158, in feed_update
    response = await self.update.wrap_outer_middleware(
  File "/Users/matvei/PycharmProjects/testoviy/.venv/lib/python3.9/site-packages/aiogram/dispatcher/middlewares/error.py", line 25, in __call__
    return await handler(event, data)
  File "/Users/matvei/PycharmProjects/testoviy/.venv/lib/python3.9/site-packages/aiogram/dispatcher/middlewares/user_context.py", line 56, in __call__
    return await handler(event, data)
  File "/Users/matvei/PycharmProjects/testoviy/.venv/lib/python3.9/site-packages/aiogram/fsm/middleware.py", line 42, in __call__
    return await handler(event, data)
  File "/Users/matvei/PycharmProjects/testoviy/.venv/lib/python3.9/site-packages/aiogram/dispatcher/event/telegram.py", line 121, in trigger
    return await wrapped_inner(event, kwargs)
  File "/Users/matvei/PycharmProjects/testoviy/.venv/lib/python3.9/site-packages/aiogram/dispatcher/event/handler.py", line 43, in call
    return await wrapped()
  File "/Users/matvei/PycharmProjects/testoviy/.venv/lib/python3.9/site-packages/aiogram/dispatcher/dispatcher.py", line 276, in _listen_update
    return await self.propagate_event(update_type=update_type, event=event, **kwargs)
  File "/Users/matvei/PycharmProjects/testoviy/.venv/lib/python3.9/site-packages/aiogram/dispatcher/router.py", line 146, in propagate_event
    return await observer.wrap_outer_middleware(_wrapped, event=event, data=kwargs)
  File "/Users/matvei/PycharmProjects/testoviy/.venv/lib/python3.9/site-packages/aiogram/dispatcher/router.py", line 141, in _wrapped
    return await self._propagate_event(
  File "/Users/matvei/PycharmProjects/testoviy/.venv/lib/python3.9/site-packages/aiogram/dispatcher/router.py", line 174, in _propagate_event
    response = await router.propagate_event(update_type=update_type, event=event, **kwargs)
  File "/Users/matvei/PycharmProjects/testoviy/.venv/lib/python3.9/site-packages/aiogram/dispatcher/router.py", line 146, in propagate_event
    return await observer.wrap_outer_middleware(_wrapped, event=event, data=kwargs)
  File "/Users/matvei/PycharmProjects/testoviy/.venv/lib/python3.9/site-packages/aiogram/dispatcher/router.py", line 141, in _wrapped
    return await self._propagate_event(
  File "/Users/matvei/PycharmProjects/testoviy/.venv/lib/python3.9/site-packages/aiogram/dispatcher/router.py", line 166, in _propagate_event
    response = await observer.trigger(event, **kwargs)
  File "/Users/matvei/PycharmProjects/testoviy/.venv/lib/python3.9/site-packages/aiogram/dispatcher/event/telegram.py", line 121, in trigger
    return await wrapped_inner(event, kwargs)
  File "/Users/matvei/PycharmProjects/testoviy/.venv/lib/python3.9/site-packages/aiogram/dispatcher/event/handler.py", line 43, in call
    return await wrapped()
  File "/Users/matvei/PycharmProjects/testoviy/handlers.py", line 55, in recount
    errors = money_recount()
  File "/Users/matvei/PycharmProjects/testoviy/calendar_myad.py", line 62, in recount
    events_result = service.events().list(
  File "/Users/matvei/PycharmProjects/testoviy/.venv/lib/python3.9/site-packages/googleapiclient/_helpers.py", line 130, in positional_wrapper
    return wrapped(*args, **kwargs)
  File "/Users/matvei/PycharmProjects/testoviy/.venv/lib/python3.9/site-packages/googleapiclient/http.py", line 938, in execute
    raise HttpError(resp, content, uri=self.uri)
googleapiclient.errors.HttpError: <HttpError 404 when requesting https://www.googleapis.com/calendar/v3/calendars/%7B%7D/events?timeMin=2024-12-11T18%3A25%3A18Z&timeMax=2024-12-11T18%3A25%3A46Z&singleEvents=true&orderBy=startTime&alt=json returned "Not Found". Details: "[{'domain': 'global', 'reason': 'notFound', 'message': 'Not Found'}]">
2024-12-11 18:25:50,275 INFO file_cache is only supported with oauth2client<4.0.0
2024-12-11 18:25:50,564 INFO Update id=301615577 is not handled. Duration 292 ms by bot id=7546513983
2024-12-11 18:25:50,564 ERROR Cause exception while process update id=301615577 by bot id=7546513983
HttpError: <HttpError 404 when requesting https://www.googleapis.com/calendar/v3/calendars/%7B%7D/events?timeMin=2024-12-11T18%3A25%3A46Z&timeMax=2024-12-11T18%3A25%3A50Z&singleEvents=true&orderBy=startTime&alt=json returned "Not Found". Details: "[{'domain': 'global', 'reason': 'notFound', 'message': 'Not Found'}]">
Traceback (most recent call last):
  File "/Users/matvei/PycharmProjects/testoviy/.venv/lib/python3.9/site-packages/aiogram/dispatcher/dispatcher.py", line 309, in _process_update
    response = await self.feed_update(bot, update, **kwargs)
  File "/Users/matvei/PycharmProjects/testoviy/.venv/lib/python3.9/site-packages/aiogram/dispatcher/dispatcher.py", line 158, in feed_update
    response = await self.update.wrap_outer_middleware(
  File "/Users/matvei/PycharmProjects/testoviy/.venv/lib/python3.9/site-packages/aiogram/dispatcher/middlewares/error.py", line 25, in __call__
    return await handler(event, data)
  File "/Users/matvei/PycharmProjects/testoviy/.venv/lib/python3.9/site-packages/aiogram/dispatcher/middlewares/user_context.py", line 56, in __call__
    return await handler(event, data)
  File "/Users/matvei/PycharmProjects/testoviy/.venv/lib/python3.9/site-packages/aiogram/fsm/middleware.py", line 42, in __call__
    return await handler(event, data)
  File "/Users/matvei/PycharmProjects/testoviy/.venv/lib/python3.9/site-packages/aiogram/dispatcher/event/telegram.py", line 121, in trigger
    return await wrapped_inner(event, kwargs)
  File "/Users/matvei/PycharmProjects/testoviy/.venv/lib/python3.9/site-packages/aiogram/dispatcher/event/handler.py", line 43, in call
    return await wrapped()
  File "/Users/matvei/PycharmProjects/testoviy/.venv/lib/python3.9/site-packages/aiogram/dispatcher/dispatcher.py", line 276, in _listen_update
    return await self.propagate_event(update_type=update_type, event=event, **kwargs)
  File "/Users/matvei/PycharmProjects/testoviy/.venv/lib/python3.9/site-packages/aiogram/dispatcher/router.py", line 146, in propagate_event
    return await observer.wrap_outer_middleware(_wrapped, event=event, data=kwargs)
  File "/Users/matvei/PycharmProjects/testoviy/.venv/lib/python3.9/site-packages/aiogram/dispatcher/router.py", line 141, in _wrapped
    return await self._propagate_event(
  File "/Users/matvei/PycharmProjects/testoviy/.venv/lib/python3.9/site-packages/aiogram/dispatcher/router.py", line 174, in _propagate_event
    response = await router.propagate_event(update_type=update_type, event=event, **kwargs)
  File "/Users/matvei/PycharmProjects/testoviy/.venv/lib/python3.9/site-packages/aiogram/dispatcher/router.py", line 146, in propagate_event
    return await observer.wrap_outer_middleware(_wrapped, event=event, data=kwargs)
  File "/Users/matvei/PycharmProjects/testoviy/.venv/lib/python3.9/site-packages/aiogram/dispatcher/router.py", line 141, in _wrapped
    return await self._propagate_event(
  File "/Users/matvei/PycharmProjects/testoviy/.venv/lib/python3.9/site-packages/aiogram/dispatcher/router.py", line 166, in _propagate_event
    response = await observer.trigger(event, **kwargs)
  File "/Users/matvei/PycharmProjects/testoviy/.venv/lib/python3.9/site-packages/aiogram/dispatcher/event/telegram.py", line 121, in trigger
    return await wrapped_inner(event, kwargs)
  File "/Users/matvei/PycharmProjects/testoviy/.venv/lib/python3.9/site-packages/aiogram/dispatcher/event/handler.py", line 43, in call
    return await wrapped()
  File "/Users/matvei/PycharmProjects/testoviy/handlers.py", line 55, in recount
    errors = money_recount()
  File "/Users/matvei/PycharmProjects/testoviy/calendar_myad.py", line 62, in recount
    events_result = service.events().list(
  File "/Users/matvei/PycharmProjects/testoviy/.venv/lib/python3.9/site-packages/googleapiclient/_helpers.py", line 130, in positional_wrapper
    return wrapped(*args, **kwargs)
  File "/Users/matvei/PycharmProjects/testoviy/.venv/lib/python3.9/site-packages/googleapiclient/http.py", line 938, in execute
    raise HttpError(resp, content, uri=self.uri)
googleapiclient.errors.HttpError: <HttpError 404 when requesting https://www.googleapis.com/calendar/v3/calendars/%7B%7D/events?timeMin=2024-12-11T18%3A25%3A46Z&timeMax=2024-12-11T18%3A25%3A50Z&singleEvents=true&orderBy=startTime&alt=json returned "Not Found". Details: "[{'domain': 'global', 'reason': 'notFound', 'message': 'Not Found'}]">
2024-12-11 18:26:38,567 WARNING Received SIGINT signal
2024-12-11 18:26:38,567 INFO Polling stopped for bot @matveykalobot id=7546513983 - 'великий бот матвейки'
2024-12-11 18:26:38,568 INFO Polling stopped
2024-12-11 18:26:44,119 INFO Start polling
2024-12-11 18:26:44,339 INFO Run polling for bot @matveykalobot id=7546513983 - 'великий бот матвейки'
2024-12-11 18:26:44,437 INFO file_cache is only supported with oauth2client<4.0.0
2024-12-11 18:26:44,758 INFO Update id=301615578 is not handled. Duration 324 ms by bot id=7546513983
2024-12-11 18:26:44,758 ERROR Cause exception while process update id=301615578 by bot id=7546513983
HttpError: <HttpError 404 when requesting https://www.googleapis.com/calendar/v3/calendars/%7B%7D/events?timeMin=2024-12-11T18%3A25%3A50Z&timeMax=2024-12-11T18%3A26%3A44Z&singleEvents=true&orderBy=startTime&alt=json returned "Not Found". Details: "[{'domain': 'global', 'reason': 'notFound', 'message': 'Not Found'}]">
Traceback (most recent call last):
  File "/Users/matvei/PycharmProjects/testoviy/.venv/lib/python3.9/site-packages/aiogram/dispatcher/dispatcher.py", line 309, in _process_update
    response = await self.feed_update(bot, update, **kwargs)
  File "/Users/matvei/PycharmProjects/testoviy/.venv/lib/python3.9/site-packages/aiogram/dispatcher/dispatcher.py", line 158, in feed_update
    response = await self.update.wrap_outer_middleware(
  File "/Users/matvei/PycharmProjects/testoviy/.venv/lib/python3.9/site-packages/aiogram/dispatcher/middlewares/error.py", line 25, in __call__
    return await handler(event, data)
  File "/Users/matvei/PycharmProjects/testoviy/.venv/lib/python3.9/site-packages/aiogram/dispatcher/middlewares/user_context.py", line 56, in __call__
    return await handler(event, data)
  File "/Users/matvei/PycharmProjects/testoviy/.venv/lib/python3.9/site-packages/aiogram/fsm/middleware.py", line 42, in __call__
    return await handler(event, data)
  File "/Users/matvei/PycharmProjects/testoviy/.venv/lib/python3.9/site-packages/aiogram/dispatcher/event/telegram.py", line 121, in trigger
    return await wrapped_inner(event, kwargs)
  File "/Users/matvei/PycharmProjects/testoviy/.venv/lib/python3.9/site-packages/aiogram/dispatcher/event/handler.py", line 43, in call
    return await wrapped()
  File "/Users/matvei/PycharmProjects/testoviy/.venv/lib/python3.9/site-packages/aiogram/dispatcher/dispatcher.py", line 276, in _listen_update
    return await self.propagate_event(update_type=update_type, event=event, **kwargs)
  File "/Users/matvei/PycharmProjects/testoviy/.venv/lib/python3.9/site-packages/aiogram/dispatcher/router.py", line 146, in propagate_event
    return await observer.wrap_outer_middleware(_wrapped, event=event, data=kwargs)
  File "/Users/matvei/PycharmProjects/testoviy/.venv/lib/python3.9/site-packages/aiogram/dispatcher/router.py", line 141, in _wrapped
    return await self._propagate_event(
  File "/Users/matvei/PycharmProjects/testoviy/.venv/lib/python3.9/site-packages/aiogram/dispatcher/router.py", line 174, in _propagate_event
    response = await router.propagate_event(update_type=update_type, event=event, **kwargs)
  File "/Users/matvei/PycharmProjects/testoviy/.venv/lib/python3.9/site-packages/aiogram/dispatcher/router.py", line 146, in propagate_event
    return await observer.wrap_outer_middleware(_wrapped, event=event, data=kwargs)
  File "/Users/matvei/PycharmProjects/testoviy/.venv/lib/python3.9/site-packages/aiogram/dispatcher/router.py", line 141, in _wrapped
    return await self._propagate_event(
  File "/Users/matvei/PycharmProjects/testoviy/.venv/lib/python3.9/site-packages/aiogram/dispatcher/router.py", line 166, in _propagate_event
    response = await observer.trigger(event, **kwargs)
  File "/Users/matvei/PycharmProjects/testoviy/.venv/lib/python3.9/site-packages/aiogram/dispatcher/event/telegram.py", line 121, in trigger
    return await wrapped_inner(event, kwargs)
  File "/Users/matvei/PycharmProjects/testoviy/.venv/lib/python3.9/site-packages/aiogram/dispatcher/event/handler.py", line 43, in call
    return await wrapped()
  File "/Users/matvei/PycharmProjects/testoviy/handlers.py", line 55, in recount
    errors = money_recount()
  File "/Users/matvei/PycharmProjects/testoviy/calendar_myad.py", line 63, in recount
    events_result = service.events().list(
  File "/Users/matvei/PycharmProjects/testoviy/.venv/lib/python3.9/site-packages/googleapiclient/_helpers.py", line 130, in positional_wrapper
    return wrapped(*args, **kwargs)
  File "/Users/matvei/PycharmProjects/testoviy/.venv/lib/python3.9/site-packages/googleapiclient/http.py", line 938, in execute
    raise HttpError(resp, content, uri=self.uri)
googleapiclient.errors.HttpError: <HttpError 404 when requesting https://www.googleapis.com/calendar/v3/calendars/%7B%7D/events?timeMin=2024-12-11T18%3A25%3A50Z&timeMax=2024-12-11T18%3A26%3A44Z&singleEvents=true&orderBy=startTime&alt=json returned "Not Found". Details: "[{'domain': 'global', 'reason': 'notFound', 'message': 'Not Found'}]">
2024-12-11 18:26:50,376 INFO file_cache is only supported with oauth2client<4.0.0
2024-12-11 18:26:50,664 INFO Update id=301615579 is not handled. Duration 291 ms by bot id=7546513983
2024-12-11 18:26:50,664 ERROR Cause exception while process update id=301615579 by bot id=7546513983
HttpError: <HttpError 404 when requesting https://www.googleapis.com/calendar/v3/calendars/%7B%7D/events?timeMin=2024-12-11T18%3A26%3A44Z&timeMax=2024-12-11T18%3A26%3A50Z&singleEvents=true&orderBy=startTime&alt=json returned "Not Found". Details: "[{'domain': 'global', 'reason': 'notFound', 'message': 'Not Found'}]">
Traceback (most recent call last):
  File "/Users/matvei/PycharmProjects/testoviy/.venv/lib/python3.9/site-packages/aiogram/dispatcher/dispatcher.py", line 309, in _process_update
    response = await self.feed_update(bot, update, **kwargs)
  File "/Users/matvei/PycharmProjects/testoviy/.venv/lib/python3.9/site-packages/aiogram/dispatcher/dispatcher.py", line 158, in feed_update
    response = await self.update.wrap_outer_middleware(
  File "/Users/matvei/PycharmProjects/testoviy/.venv/lib/python3.9/site-packages/aiogram/dispatcher/middlewares/error.py", line 25, in __call__
    return await handler(event, data)
  File "/Users/matvei/PycharmProjects/testoviy/.venv/lib/python3.9/site-packages/aiogram/dispatcher/middlewares/user_context.py", line 56, in __call__
    return await handler(event, data)
  File "/Users/matvei/PycharmProjects/testoviy/.venv/lib/python3.9/site-packages/aiogram/fsm/middleware.py", line 42, in __call__
    return await handler(event, data)
  File "/Users/matvei/PycharmProjects/testoviy/.venv/lib/python3.9/site-packages/aiogram/dispatcher/event/telegram.py", line 121, in trigger
    return await wrapped_inner(event, kwargs)
  File "/Users/matvei/PycharmProjects/testoviy/.venv/lib/python3.9/site-packages/aiogram/dispatcher/event/handler.py", line 43, in call
    return await wrapped()
  File "/Users/matvei/PycharmProjects/testoviy/.venv/lib/python3.9/site-packages/aiogram/dispatcher/dispatcher.py", line 276, in _listen_update
    return await self.propagate_event(update_type=update_type, event=event, **kwargs)
  File "/Users/matvei/PycharmProjects/testoviy/.venv/lib/python3.9/site-packages/aiogram/dispatcher/router.py", line 146, in propagate_event
    return await observer.wrap_outer_middleware(_wrapped, event=event, data=kwargs)
  File "/Users/matvei/PycharmProjects/testoviy/.venv/lib/python3.9/site-packages/aiogram/dispatcher/router.py", line 141, in _wrapped
    return await self._propagate_event(
  File "/Users/matvei/PycharmProjects/testoviy/.venv/lib/python3.9/site-packages/aiogram/dispatcher/router.py", line 174, in _propagate_event
    response = await router.propagate_event(update_type=update_type, event=event, **kwargs)
  File "/Users/matvei/PycharmProjects/testoviy/.venv/lib/python3.9/site-packages/aiogram/dispatcher/router.py", line 146, in propagate_event
    return await observer.wrap_outer_middleware(_wrapped, event=event, data=kwargs)
  File "/Users/matvei/PycharmProjects/testoviy/.venv/lib/python3.9/site-packages/aiogram/dispatcher/router.py", line 141, in _wrapped
    return await self._propagate_event(
  File "/Users/matvei/PycharmProjects/testoviy/.venv/lib/python3.9/site-packages/aiogram/dispatcher/router.py", line 166, in _propagate_event
    response = await observer.trigger(event, **kwargs)
  File "/Users/matvei/PycharmProjects/testoviy/.venv/lib/python3.9/site-packages/aiogram/dispatcher/event/telegram.py", line 121, in trigger
    return await wrapped_inner(event, kwargs)
  File "/Users/matvei/PycharmProjects/testoviy/.venv/lib/python3.9/site-packages/aiogram/dispatcher/event/handler.py", line 43, in call
    return await wrapped()
  File "/Users/matvei/PycharmProjects/testoviy/handlers.py", line 55, in recount
    errors = money_recount()
  File "/Users/matvei/PycharmProjects/testoviy/calendar_myad.py", line 63, in recount
    events_result = service.events().list(
  File "/Users/matvei/PycharmProjects/testoviy/.venv/lib/python3.9/site-packages/googleapiclient/_helpers.py", line 130, in positional_wrapper
    return wrapped(*args, **kwargs)
  File "/Users/matvei/PycharmProjects/testoviy/.venv/lib/python3.9/site-packages/googleapiclient/http.py", line 938, in execute
    raise HttpError(resp, content, uri=self.uri)
googleapiclient.errors.HttpError: <HttpError 404 when requesting https://www.googleapis.com/calendar/v3/calendars/%7B%7D/events?timeMin=2024-12-11T18%3A26%3A44Z&timeMax=2024-12-11T18%3A26%3A50Z&singleEvents=true&orderBy=startTime&alt=json returned "Not Found". Details: "[{'domain': 'global', 'reason': 'notFound', 'message': 'Not Found'}]">
2024-12-11 18:27:17,739 WARNING Received SIGINT signal
2024-12-11 18:27:17,740 INFO Polling stopped for bot @matveykalobot id=7546513983 - 'великий бот матвейки'
2024-12-11 18:27:17,740 INFO Polling stopped
2024-12-11 18:27:22,456 INFO Start polling
2024-12-11 18:27:22,675 INFO Run polling for bot @matveykalobot id=7546513983 - 'великий бот матвейки'
2024-12-11 18:27:22,768 INFO file_cache is only supported with oauth2client<4.0.0
2024-12-11 18:27:23,039 INFO Update id=301615580 is not handled. Duration 275 ms by bot id=7546513983
2024-12-11 18:27:23,039 ERROR Cause exception while process update id=301615580 by bot id=7546513983
HttpError: <HttpError 404 when requesting https://www.googleapis.com/calendar/v3/calendars/%7B%7D/events?timeMin=2024-12-11T18%3A26%3A50Z&timeMax=2024-12-11T18%3A27%3A22Z&singleEvents=true&orderBy=startTime&alt=json returned "Not Found". Details: "[{'domain': 'global', 'reason': 'notFound', 'message': 'Not Found'}]">
Traceback (most recent call last):
  File "/Users/matvei/PycharmProjects/testoviy/.venv/lib/python3.9/site-packages/aiogram/dispatcher/dispatcher.py", line 309, in _process_update
    response = await self.feed_update(bot, update, **kwargs)
  File "/Users/matvei/PycharmProjects/testoviy/.venv/lib/python3.9/site-packages/aiogram/dispatcher/dispatcher.py", line 158, in feed_update
    response = await self.update.wrap_outer_middleware(
  File "/Users/matvei/PycharmProjects/testoviy/.venv/lib/python3.9/site-packages/aiogram/dispatcher/middlewares/error.py", line 25, in __call__
    return await handler(event, data)
  File "/Users/matvei/PycharmProjects/testoviy/.venv/lib/python3.9/site-packages/aiogram/dispatcher/middlewares/user_context.py", line 56, in __call__
    return await handler(event, data)
  File "/Users/matvei/PycharmProjects/testoviy/.venv/lib/python3.9/site-packages/aiogram/fsm/middleware.py", line 42, in __call__
    return await handler(event, data)
  File "/Users/matvei/PycharmProjects/testoviy/.venv/lib/python3.9/site-packages/aiogram/dispatcher/event/telegram.py", line 121, in trigger
    return await wrapped_inner(event, kwargs)
  File "/Users/matvei/PycharmProjects/testoviy/.venv/lib/python3.9/site-packages/aiogram/dispatcher/event/handler.py", line 43, in call
    return await wrapped()
  File "/Users/matvei/PycharmProjects/testoviy/.venv/lib/python3.9/site-packages/aiogram/dispatcher/dispatcher.py", line 276, in _listen_update
    return await self.propagate_event(update_type=update_type, event=event, **kwargs)
  File "/Users/matvei/PycharmProjects/testoviy/.venv/lib/python3.9/site-packages/aiogram/dispatcher/router.py", line 146, in propagate_event
    return await observer.wrap_outer_middleware(_wrapped, event=event, data=kwargs)
  File "/Users/matvei/PycharmProjects/testoviy/.venv/lib/python3.9/site-packages/aiogram/dispatcher/router.py", line 141, in _wrapped
    return await self._propagate_event(
  File "/Users/matvei/PycharmProjects/testoviy/.venv/lib/python3.9/site-packages/aiogram/dispatcher/router.py", line 174, in _propagate_event
    response = await router.propagate_event(update_type=update_type, event=event, **kwargs)
  File "/Users/matvei/PycharmProjects/testoviy/.venv/lib/python3.9/site-packages/aiogram/dispatcher/router.py", line 146, in propagate_event
    return await observer.wrap_outer_middleware(_wrapped, event=event, data=kwargs)
  File "/Users/matvei/PycharmProjects/testoviy/.venv/lib/python3.9/site-packages/aiogram/dispatcher/router.py", line 141, in _wrapped
    return await self._propagate_event(
  File "/Users/matvei/PycharmProjects/testoviy/.venv/lib/python3.9/site-packages/aiogram/dispatcher/router.py", line 166, in _propagate_event
    response = await observer.trigger(event, **kwargs)
  File "/Users/matvei/PycharmProjects/testoviy/.venv/lib/python3.9/site-packages/aiogram/dispatcher/event/telegram.py", line 121, in trigger
    return await wrapped_inner(event, kwargs)
  File "/Users/matvei/PycharmProjects/testoviy/.venv/lib/python3.9/site-packages/aiogram/dispatcher/event/handler.py", line 43, in call
    return await wrapped()
  File "/Users/matvei/PycharmProjects/testoviy/handlers.py", line 55, in recount
    errors = money_recount()
  File "/Users/matvei/PycharmProjects/testoviy/calendar_myad.py", line 64, in recount
    events_result = service.events().list(
  File "/Users/matvei/PycharmProjects/testoviy/.venv/lib/python3.9/site-packages/googleapiclient/_helpers.py", line 130, in positional_wrapper
    return wrapped(*args, **kwargs)
  File "/Users/matvei/PycharmProjects/testoviy/.venv/lib/python3.9/site-packages/googleapiclient/http.py", line 938, in execute
    raise HttpError(resp, content, uri=self.uri)
googleapiclient.errors.HttpError: <HttpError 404 when requesting https://www.googleapis.com/calendar/v3/calendars/%7B%7D/events?timeMin=2024-12-11T18%3A26%3A50Z&timeMax=2024-12-11T18%3A27%3A22Z&singleEvents=true&orderBy=startTime&alt=json returned "Not Found". Details: "[{'domain': 'global', 'reason': 'notFound', 'message': 'Not Found'}]">
2024-12-11 18:29:14,849 WARNING Received SIGINT signal
2024-12-11 18:29:14,850 INFO Polling stopped for bot @matveykalobot id=7546513983 - 'великий бот матвейки'
2024-12-11 18:29:14,850 INFO Polling stopped
2024-12-11 18:29:20,000 INFO Start polling
2024-12-11 18:29:20,234 INFO Run polling for bot @matveykalobot id=7546513983 - 'великий бот матвейки'
2024-12-11 18:29:20,341 INFO file_cache is only supported with oauth2client<4.0.0
2024-12-11 18:29:20,678 INFO Update id=301615581 is not handled. Duration 344 ms by bot id=7546513983
2024-12-11 18:29:20,679 ERROR Cause exception while process update id=301615581 by bot id=7546513983
HttpError: <HttpError 404 when requesting https://www.googleapis.com/calendar/v3/calendars/%7B%7D/events?timeMin=2024-12-11T18%3A27%3A22Z&timeMax=2024-12-11T18%3A29%3A20Z&singleEvents=true&orderBy=startTime&alt=json returned "Not Found". Details: "[{'domain': 'global', 'reason': 'notFound', 'message': 'Not Found'}]">
Traceback (most recent call last):
  File "/Users/matvei/PycharmProjects/testoviy/.venv/lib/python3.9/site-packages/aiogram/dispatcher/dispatcher.py", line 309, in _process_update
    response = await self.feed_update(bot, update, **kwargs)
  File "/Users/matvei/PycharmProjects/testoviy/.venv/lib/python3.9/site-packages/aiogram/dispatcher/dispatcher.py", line 158, in feed_update
    response = await self.update.wrap_outer_middleware(
  File "/Users/matvei/PycharmProjects/testoviy/.venv/lib/python3.9/site-packages/aiogram/dispatcher/middlewares/error.py", line 25, in __call__
    return await handler(event, data)
  File "/Users/matvei/PycharmProjects/testoviy/.venv/lib/python3.9/site-packages/aiogram/dispatcher/middlewares/user_context.py", line 56, in __call__
    return await handler(event, data)
  File "/Users/matvei/PycharmProjects/testoviy/.venv/lib/python3.9/site-packages/aiogram/fsm/middleware.py", line 42, in __call__
    return await handler(event, data)
  File "/Users/matvei/PycharmProjects/testoviy/.venv/lib/python3.9/site-packages/aiogram/dispatcher/event/telegram.py", line 121, in trigger
    return await wrapped_inner(event, kwargs)
  File "/Users/matvei/PycharmProjects/testoviy/.venv/lib/python3.9/site-packages/aiogram/dispatcher/event/handler.py", line 43, in call
    return await wrapped()
  File "/Users/matvei/PycharmProjects/testoviy/.venv/lib/python3.9/site-packages/aiogram/dispatcher/dispatcher.py", line 276, in _listen_update
    return await self.propagate_event(update_type=update_type, event=event, **kwargs)
  File "/Users/matvei/PycharmProjects/testoviy/.venv/lib/python3.9/site-packages/aiogram/dispatcher/router.py", line 146, in propagate_event
    return await observer.wrap_outer_middleware(_wrapped, event=event, data=kwargs)
  File "/Users/matvei/PycharmProjects/testoviy/.venv/lib/python3.9/site-packages/aiogram/dispatcher/router.py", line 141, in _wrapped
    return await self._propagate_event(
  File "/Users/matvei/PycharmProjects/testoviy/.venv/lib/python3.9/site-packages/aiogram/dispatcher/router.py", line 174, in _propagate_event
    response = await router.propagate_event(update_type=update_type, event=event, **kwargs)
  File "/Users/matvei/PycharmProjects/testoviy/.venv/lib/python3.9/site-packages/aiogram/dispatcher/router.py", line 146, in propagate_event
    return await observer.wrap_outer_middleware(_wrapped, event=event, data=kwargs)
  File "/Users/matvei/PycharmProjects/testoviy/.venv/lib/python3.9/site-packages/aiogram/dispatcher/router.py", line 141, in _wrapped
    return await self._propagate_event(
  File "/Users/matvei/PycharmProjects/testoviy/.venv/lib/python3.9/site-packages/aiogram/dispatcher/router.py", line 166, in _propagate_event
    response = await observer.trigger(event, **kwargs)
  File "/Users/matvei/PycharmProjects/testoviy/.venv/lib/python3.9/site-packages/aiogram/dispatcher/event/telegram.py", line 121, in trigger
    return await wrapped_inner(event, kwargs)
  File "/Users/matvei/PycharmProjects/testoviy/.venv/lib/python3.9/site-packages/aiogram/dispatcher/event/handler.py", line 43, in call
    return await wrapped()
  File "/Users/matvei/PycharmProjects/testoviy/handlers.py", line 55, in recount
    errors = money_recount()
  File "/Users/matvei/PycharmProjects/testoviy/calendar_myad.py", line 63, in recount
    events_result = service.events().list(
  File "/Users/matvei/PycharmProjects/testoviy/.venv/lib/python3.9/site-packages/googleapiclient/_helpers.py", line 130, in positional_wrapper
    return wrapped(*args, **kwargs)
  File "/Users/matvei/PycharmProjects/testoviy/.venv/lib/python3.9/site-packages/googleapiclient/http.py", line 938, in execute
    raise HttpError(resp, content, uri=self.uri)
googleapiclient.errors.HttpError: <HttpError 404 when requesting https://www.googleapis.com/calendar/v3/calendars/%7B%7D/events?timeMin=2024-12-11T18%3A27%3A22Z&timeMax=2024-12-11T18%3A29%3A20Z&singleEvents=true&orderBy=startTime&alt=json returned "Not Found". Details: "[{'domain': 'global', 'reason': 'notFound', 'message': 'Not Found'}]">
2024-12-11 18:30:31,389 WARNING Received SIGINT signal
2024-12-11 18:30:31,390 INFO Polling stopped for bot @matveykalobot id=7546513983 - 'великий бот матвейки'
2024-12-11 18:30:31,391 INFO Polling stopped
2024-12-11 18:30:49,810 INFO Start polling
2024-12-11 18:30:50,043 INFO Run polling for bot @matveykalobot id=7546513983 - 'великий бот матвейки'
2024-12-11 18:30:50,130 INFO file_cache is only supported with oauth2client<4.0.0
2024-12-11 18:30:50,464 INFO Update id=301615582 is not handled. Duration 340 ms by bot id=7546513983
2024-12-11 18:30:50,464 ERROR Cause exception while process update id=301615582 by bot id=7546513983
HttpError: <HttpError 404 when requesting https://www.googleapis.com/calendar/v3/calendars/%7B%7D/events?timeMin=2024-12-11T18%3A29%3A20Z&timeMax=2024-12-11T18%3A30%3A50Z&singleEvents=true&orderBy=startTime&alt=json returned "Not Found". Details: "[{'domain': 'global', 'reason': 'notFound', 'message': 'Not Found'}]">
Traceback (most recent call last):
  File "/Users/matvei/PycharmProjects/testoviy/.venv/lib/python3.9/site-packages/aiogram/dispatcher/dispatcher.py", line 309, in _process_update
    response = await self.feed_update(bot, update, **kwargs)
  File "/Users/matvei/PycharmProjects/testoviy/.venv/lib/python3.9/site-packages/aiogram/dispatcher/dispatcher.py", line 158, in feed_update
    response = await self.update.wrap_outer_middleware(
  File "/Users/matvei/PycharmProjects/testoviy/.venv/lib/python3.9/site-packages/aiogram/dispatcher/middlewares/error.py", line 25, in __call__
    return await handler(event, data)
  File "/Users/matvei/PycharmProjects/testoviy/.venv/lib/python3.9/site-packages/aiogram/dispatcher/middlewares/user_context.py", line 56, in __call__
    return await handler(event, data)
  File "/Users/matvei/PycharmProjects/testoviy/.venv/lib/python3.9/site-packages/aiogram/fsm/middleware.py", line 42, in __call__
    return await handler(event, data)
  File "/Users/matvei/PycharmProjects/testoviy/.venv/lib/python3.9/site-packages/aiogram/dispatcher/event/telegram.py", line 121, in trigger
    return await wrapped_inner(event, kwargs)
  File "/Users/matvei/PycharmProjects/testoviy/.venv/lib/python3.9/site-packages/aiogram/dispatcher/event/handler.py", line 43, in call
    return await wrapped()
  File "/Users/matvei/PycharmProjects/testoviy/.venv/lib/python3.9/site-packages/aiogram/dispatcher/dispatcher.py", line 276, in _listen_update
    return await self.propagate_event(update_type=update_type, event=event, **kwargs)
  File "/Users/matvei/PycharmProjects/testoviy/.venv/lib/python3.9/site-packages/aiogram/dispatcher/router.py", line 146, in propagate_event
    return await observer.wrap_outer_middleware(_wrapped, event=event, data=kwargs)
  File "/Users/matvei/PycharmProjects/testoviy/.venv/lib/python3.9/site-packages/aiogram/dispatcher/router.py", line 141, in _wrapped
    return await self._propagate_event(
  File "/Users/matvei/PycharmProjects/testoviy/.venv/lib/python3.9/site-packages/aiogram/dispatcher/router.py", line 174, in _propagate_event
    response = await router.propagate_event(update_type=update_type, event=event, **kwargs)
  File "/Users/matvei/PycharmProjects/testoviy/.venv/lib/python3.9/site-packages/aiogram/dispatcher/router.py", line 146, in propagate_event
    return await observer.wrap_outer_middleware(_wrapped, event=event, data=kwargs)
  File "/Users/matvei/PycharmProjects/testoviy/.venv/lib/python3.9/site-packages/aiogram/dispatcher/router.py", line 141, in _wrapped
    return await self._propagate_event(
  File "/Users/matvei/PycharmProjects/testoviy/.venv/lib/python3.9/site-packages/aiogram/dispatcher/router.py", line 166, in _propagate_event
    response = await observer.trigger(event, **kwargs)
  File "/Users/matvei/PycharmProjects/testoviy/.venv/lib/python3.9/site-packages/aiogram/dispatcher/event/telegram.py", line 121, in trigger
    return await wrapped_inner(event, kwargs)
  File "/Users/matvei/PycharmProjects/testoviy/.venv/lib/python3.9/site-packages/aiogram/dispatcher/event/handler.py", line 43, in call
    return await wrapped()
  File "/Users/matvei/PycharmProjects/testoviy/handlers.py", line 55, in recount
    errors = money_recount()
  File "/Users/matvei/PycharmProjects/testoviy/calendar_myad.py", line 64, in recount
    events_result = service.events().list(
  File "/Users/matvei/PycharmProjects/testoviy/.venv/lib/python3.9/site-packages/googleapiclient/_helpers.py", line 130, in positional_wrapper
    return wrapped(*args, **kwargs)
  File "/Users/matvei/PycharmProjects/testoviy/.venv/lib/python3.9/site-packages/googleapiclient/http.py", line 938, in execute
    raise HttpError(resp, content, uri=self.uri)
googleapiclient.errors.HttpError: <HttpError 404 when requesting https://www.googleapis.com/calendar/v3/calendars/%7B%7D/events?timeMin=2024-12-11T18%3A29%3A20Z&timeMax=2024-12-11T18%3A30%3A50Z&singleEvents=true&orderBy=startTime&alt=json returned "Not Found". Details: "[{'domain': 'global', 'reason': 'notFound', 'message': 'Not Found'}]">
2024-12-11 18:32:27,749 WARNING Received SIGINT signal
2024-12-11 18:32:27,750 INFO Polling stopped for bot @matveykalobot id=7546513983 - 'великий бот матвейки'
2024-12-11 18:32:27,750 INFO Polling stopped
2024-12-11 18:32:33,092 INFO Start polling
2024-12-11 18:32:33,722 INFO Run polling for bot @matveykalobot id=7546513983 - 'великий бот матвейки'
2024-12-11 18:32:33,810 INFO file_cache is only supported with oauth2client<4.0.0
2024-12-11 18:32:34,511 INFO Update id=301615583 is handled. Duration 705 ms by bot id=7546513983
2024-12-11 18:33:31,515 WARNING Received SIGINT signal
2024-12-11 18:33:31,516 INFO Polling stopped for bot @matveykalobot id=7546513983 - 'великий бот матвейки'
2024-12-11 18:33:31,516 INFO Polling stopped
2024-12-11 18:33:37,411 INFO Start polling
2024-12-11 18:33:37,654 INFO Run polling for bot @matveykalobot id=7546513983 - 'великий бот матвейки'
2024-12-11 18:33:37,742 INFO file_cache is only supported with oauth2client<4.0.0
2024-12-11 18:33:38,109 INFO Update id=301615584 is handled. Duration 373 ms by bot id=7546513983
2024-12-11 18:33:49,145 INFO file_cache is only supported with oauth2client<4.0.0
2024-12-11 18:33:49,498 INFO Update id=301615585 is handled. Duration 355 ms by bot id=7546513983
2024-12-11 18:34:34,625 INFO file_cache is only supported with oauth2client<4.0.0
2024-12-11 18:34:34,980 INFO Update id=301615586 is handled. Duration 359 ms by bot id=7546513983
2024-12-11 18:37:26,476 WARNING Received SIGINT signal
2024-12-11 18:37:26,477 INFO Polling stopped for bot @matveykalobot id=7546513983 - 'великий бот матвейки'
2024-12-11 18:37:26,477 INFO Polling stopped
2024-12-11 18:37:31,728 INFO Start polling
2024-12-11 18:37:31,966 INFO Run polling for bot @matveykalobot id=7546513983 - 'великий бот матвейки'
2024-12-11 18:37:37,849 INFO file_cache is only supported with oauth2client<4.0.0
2024-12-11 18:37:38,248 INFO Update id=301615587 is handled. Duration 410 ms by bot id=7546513983
2024-12-11 18:41:19,416 WARNING Received SIGINT signal
2024-12-11 18:41:19,417 INFO Polling stopped for bot @matveykalobot id=7546513983 - 'великий бот матвейки'
2024-12-11 18:41:19,417 INFO Polling stopped
2024-12-11 18:41:24,764 INFO Start polling
2024-12-11 18:41:25,003 INFO Run polling for bot @matveykalobot id=7546513983 - 'великий бот матвейки'
2024-12-11 18:41:26,813 INFO file_cache is only supported with oauth2client<4.0.0
2024-12-11 18:41:27,651 INFO Update id=301615588 is handled. Duration 848 ms by bot id=7546513983
2024-12-11 18:42:19,145 WARNING Received SIGINT signal
2024-12-11 18:42:19,146 INFO Polling stopped for bot @matveykalobot id=7546513983 - 'великий бот матвейки'
2024-12-11 18:42:19,146 INFO Polling stopped
